Workbook
Name Affiche_Semaine: #REF!
Name Affiche_Semaine: #REF!
Name Affiche_Semaine: #REF!
Name Affiche_Semaine: #REF!
Name Affiche_Semaine: #REF!
Name Affiche_Semaine: #REF!
Name Affiche_Semaine: #REF!
Name Affiche_Semaine: #REF!
Name Affiche_Semaine: #REF!
Name Affiche_Semaine: #REF!
Name Affiche_Semaine: #REF!
Name Affiche_Semaine: #REF!
Name Affiche_Semaine: #REF!
Name asd: #REF!
Name asd: #REF!
Name asd: #REF!
Name asd: #REF!
Name asd: #REF!
Name asd: #REF!
Name asd: #REF!
Name asd: #REF!
Name asd: #REF!
Name asd: #REF!
Name asd: #REF!
Name asd: #REF!
Name bis: #REF!
Name bis: #REF!
Name bis: #REF!
Name bis: #REF!
Name bis: #REF!
Name bis: #REF!
Name bis: #REF!
Name bis: #REF!
Name bis: #REF!
Name bis: #REF!
Name bis: #REF!
Name bis: #REF!
Name BN: #REF!
Name BN: #REF!
Name BN: #REF!
Name BN: #REF!
Name BN: #REF!
Name BN: #REF!
Name BN: #REF!
Name BN: #REF!
Name BN: #REF!
Name CjmDuProjet: #REF!
Name CjmDuProjet: #REF!
Name CjmDuProjet: #REF!
Name CjmDuProjet: #REF!
Name CjmDuProjet: #REF!
Name CjmDuProjet: #REF!
Name CjmDuProjet: #REF!
Name CjmDuProjet: #REF!
Name CjmDuProjet: #REF!
Name CjmDuProjet: #REF!
Name CjmDuProjet: #REF!
Name CjmDuProjet: #REF!
Name CjmDuProjet: #REF!
Name Direction: #REF!

Sheet Fiche Doc
B1: FICHE DE REVUE PROJET | E1: Référence: F-AFF-13
E2: Version: 03
E3: Date: Novembre 2024
A5: Dashboard
A7: Rédigé par | B7: Vérifié par | D7: Approuvé par
A8: Abdelkarim AMARA | B8: Nadia BOUKEF | D8: Ahmed SAHLI
A9: Directeur AMOA- Réseaux HD | B9: Responsable Management Qualité | D9: Directeur Général Adjoint
A11: Date | B11: Version | C11: Motif de mise à jour
A12: 45505 | B12: 1 | C12: Création du document
A13: 45608 | B13: 2 | C13: Ajout du sheet Statistique et séparation des KPI figures du dashboard
A14: 45597 | B14: 3 | C14: Optimisation du fichier

Sheet Fiche identification
A1: Identification / Decription du projet | D1: Dashboard
A2: Project | B2: A24001 - PFS_AIE
A3: Contract ID | B3: 003/C/MINEPAT/CTS/PFS-AIE/UGP/CCCM-SPI/CSPM
A4: Client | B4: Projet Filets Sociaux Adaptatifs et Inclusion Economique
A5: Project name | B5: Mise à jour technologique et mise à niveau du SIG-I pour integrer les besoins du projet Filets Sociaux adaptatifs et d'Inclusion Economique
A6: Project Description | B6: Mise à jour technologique et mise à niveau du SIG-I pour integrer les besoins du projet Filets Sociaux adaptatifs et d'Inclusion Economique
A7: Bailleur de fonds | B7: Banque Mondiale (IDA)
A8: Modèle business (Seul/En groupement) | B8: Seul
A9: Type d'engagement Type (T&M / FP) | B9: FP
A10: Project manager | B10: Ahmed Amine Amiri
A11: Date de démarrage | B11: 45328
A12: Date de fin prévue | B12: 46058
A13: Durée du contrat Duration (En jours) | B13: 731
A15: Statut contractuel et financier initial (DI)
A16: Devise Projet | B16: FCFA
A17: Budget initial TO (incluant licences & soutraitances) | B17: 248992444
A18: Budget Licences & soutraitance (Initial) | B18: 0
A19: Avenant (O/N) | B19: Non
A20: Montant Avenant | B20: 0
A21: Total avenants | B21: 0
A22: Budget total (avenants inclus) | B22: 248992444
A23: Budget initial TO (incluant licences & soutraitances) en TND | B23: 1269861.5
A24: Budget Projet Rémunération en TND | B24: =#REF! -> #REF!
A25: Total avenants en TND | B25: 0
A26: Budget total (avenants inclus) en TND | B26: 1269861.5
A27: PPR (Provision Pour Risques) en TND | B27: =B26*5% -> 63493.073
A28: PPP (Provision Pour Pénalités) en TND | B28: 0
A29: Coût Total en TND (DI) | B29: =#REF! -> #REF!
A30: Marge nette vendue % | B30: =B31/B26 -> #VALUE!
A31: Marge nette vendue en TND | B31: l
A32: Workload vendu avenants inclus en JH | B32: 1717
A33: Workload initial en JH | B33: 1717
A34: Workload avenants en JH | B34: 0
A35: Workload Garantie en JH | B35: 75

Sheet TCC
A1: Dashboard
A5: Ressource | B5: TCC 2024 | C5: TCC (inclus FG) | D5: TCC 2025 | E5: TCC 2025 (inclus FG)
A6: Ahmed HAMADI | B6: 1813.3333 | C6: =(B6*1.7)/22 -> 140.12121 | D6: 1813.3333 | E6: =(D6*1.7)/20 -> 154.13333
A7: ASMA BELGHUITH | B7: 3310.909 | C7: =(B7*1.7)/22 -> 255.84297 | D7: 3310.909 | E7: =(D7*1.7)/20 -> 281.42726
A8: AYMEN ABID | B8: 3007.2955 | C8: =(B8*1.7)/22 -> 232.38193 | D8: 3399.7742 | E8: =(D8*1.7)/20 -> 288.9808
A9: DORSAF BABAY | B9: 7851.5715 | C9: =(B9*1.7)/22 -> 606.71234 | D9: 8379.2124 | E9: =(D9*1.7)/20 -> 712.23306
A10: FATEN ZNAIDI | B10: 6275.241 | C10: =(B10*1.7)/22 -> 484.90499 | D10: 7121.4332 | E10: =(D10*1.7)/20 -> 605.32182
A11: HASSEN BEN HMIDA | B11: 5112.3322 | C11: =(B11*1.7)/22 -> 395.04385 | D11: 5487.5059 | E11: =(D11*1.7)/20 -> 466.43801
A12: ISLEM BEN SAID | B12: 2000 | C12: =(B12*1.7)/22 -> 154.54545 | D12: 3774.1471 | E12: =(D12*1.7)/20 -> 320.8025
A13: MOATEZ ZNAIDI | B13: 1895 | C13: =(B13*1.7)/22 -> 146.43182 | D13: 3500.2622 | E13: =(D13*1.7)/20 -> 297.52229
A14: NIDHAL MAROUANI | B14: 2968.061 | C14: =(B14*1.7)/22 -> 229.35017 | D14: 4044.2673 | E14: =(D14*1.7)/20 -> 343.76272
A15: RAMI LOULOU | B15: 12540.872 | C15: =(B15*1.7)/22 -> 969.06737 | D15: 11275.647 | E15: =(D15*1.7)/20 -> 958.42999
A16: WAFA BOUSETTA | B16: 2063.53 | C16: =(B16*1.7)/22 -> 159.45459 | D16: 2180.2678 | E16: =(D16*1.7)/20 -> 185.32276
A17: AHMED AMINE AMIRI | B17: 9265.5224 | C17: =(B17*1.7)/22 -> 715.97218 | D17: 10177.751 | E17: =(D17*1.7)/20 -> 865.10884
... A23: Safouene BEN GALI | B23: 3776.3745 | C23: =(B23*1.7)/22 -> 291.81075 | D23: 3776.3745 | E23: =(D23*1.7)/20 -> 320.99183
A24: Total | B24: =SUM(B6:B23) -> 84507.322 | C24: =SUM(C6:C23) -> 6530.1113 | D24: =SUM(D6:D23) -> 89709.09 | E24: =SUM(E6:E23) -> 7625.2727
A29: Autres Frais | B29: Coût d'achat (DT) | C29: Coût de vente (DI/contrat) en DT | E29: Taux de change
A30: Frais de mission (Perdiem) | B30: =80*G24 -> 0 | C30: 0 | E30: 1 | F30: 3.4883
A31: Frais de mission (Billet) | C31: 0
A32: Autres | C32: 0

Sheet Missions
L1: 80
A2: N° | B2: PHASE | C2: Poste | D2: Ressource | E2: Date prévisionnel | F2: Date Début | G2: Date Fin | H2: Nom Bénéficiaire | I2: Billet | J2: Timbre | K2: Séjour | L2: Perdiem € | M2: Taux de change | N2: Perdiem DT | O2: Coût /Mission
A3: 1 | B3: Sprint 11 | C3: Chef de mission | D3: Ahmed BERRED | E3: 45293 | F3: 45303 | G3: 45303 | H3: Ahmed BERRED | I3: 3755.5 | J3: 60 | K3: 7 | L3: 80 | M3: 3.3728 | N3: =K3*L3*M3 -> 1888.768 | O3: =N3+J3+I3 -> 5704.268
A4: 2 | B4: Sprint 11 | C4: BA | D4: Faten Znaidi | E4: 45628 | F4: 45303 | G4: 45303 | H4: Faten Znaidi | I4: 3755.5 | J4: 60 | K4: 7 | L4: 80 | M4: 3.3728 | N4: =K4*L4*M4 -> 1888.768 | O4: =N4+J4+I4 -> 5704.268
A5: 3
A6: 4
A7: 5
A8: 6
A9: 7
A10: 8
A11: 9
A12: 10
A13: 11
M14: TOTAL | N14: =SUM(N3:N13) -> 3777.536 | O14: =SUM(O3:O13) -> 11408.536
K15: 49 | L15: 19298228 | M15: 0.0051 | O15: =M15*L15 -> 98420.963
I19: Facture 2025-05 du 03/02/2025
C20: 1073250 | D20: 1 | E20: =C20*D20 -> 1073250 | H20: Voyage/ Billet | I20: =1073250*#REF! -> #REF! | J20: =I20*3 -> #REF!
C21: 100170 | D21: 7 | E21: =C21*D21 -> 701190 | H21: Perdiem | I21: =151448*#REF! -> #REF! | J21: =I21*21 -> #REF!
C22: 11925 | D22: 7 | E22: =C22*D22 -> 83475 | H22: Transport | I22: =71550*#REF! -> #REF! | J22: =I22*7 -> #REF!
C23: 39353 | D23: 7 | E23: =C23*D23 -> 275471 | H23: Total consommé | J23: =SUM(J20:J22) -> #REF!
C24: 71550 | D24: 7 | E24: =C24*D24 -> 500850 | H24: RAC | J24: =O15-J23 -> #REF!
E27: =SUM(E20:E24) -> 2634236 | F27: =E27*0.0051 -> 13434.604
E29: 1033200 | F29: =E29/7 -> 147600

Sheet Avancement_Facturation
A2: Dashboard
C3: Total contrat HT (DT) | D3: ='Fiche identification'!B26 -> 1269861.5
A4: Mois en cours | C4: Total contrat HT (FCFA) | D4: ='Fiche identification'!B22 -> 248992444
B6: 45323 | C6: 45352 | D6: 45383 | E6: 45413 | F6: 45444 | G6: 45474 | H6: 45505 | I6: 45536 | J6: 45566 | K6: 45597 | L6: 45627 | M6: 45658 | N6: 45689 | O6: 45717 | P6: 45748 | Q6: 45778 | R6: 45809 | S6: 45839 | T6: 45870 | U6: 45901 | V6: 45931 | W6: 45962 | X6: 45992 | Y6: 46023 | Z6: 46054
A7: Num échéance | C7: 1 | F7: 2 | H7: 3 | J7: 4 | L7: 5 | N7: 6 | T7: 7 | Z7: 8
A8: Description | C8: Facture Sprint 1 | F8: Facture Sprint 2+3+4 | H8: Facture Sprint 5+6 | J8: Facture Sprint 7+8 | L8: Facture Sprint 9+10 | N8: Facture Sprint 11+12 | T8: MNT 18 premiers mois | Z8: MNT 6 derniers mois
A9: % | C9: 0.1 | F9: 0.16 | H9: 0.16 | J9: 0.16 | L9: 0.16 | T9: 0.05 | Z9: 0.05
A10: Evènement
A11: Devise | C11: FCFA | F11: FCFA | H11: FCFA | J11: FCFA | L11: FCFA | N11: FCFA | T11: FCFA | Z11: FCFA
A12: Montant | C12: =$D$4*C9 -> 24899244 | F12: =$D$4*F9 -> 39838791 | H12: =$D$4*H9 -> 39838791 | J12: =$D$4*J9 -> 39838791 | L12: =$D$4*L9 -> 39838791 | N12: =$D$4*N9 -> 0 | T12: =$D$4*T9 -> 12449622 | Z12: =$D$4*Z9 -> 12449622
A13: Montant en TND | C13: =$D$3*C9 -> 126986.15 | F13: =$D$3*F9 -> 203177.83 | H13: =$D$3*H9 -> 203177.83 | J13: =$D$3*J9 -> 203177.83 | L13: =$D$3*L9 -> 203177.83 | N13: =$D$3*N9 -> 0 | T13: =$D$3*T9 -> 63493.073 | Z13: =$D$3*Z9 -> 63493.073
A14: Reste à facturer en TND | C14: =$D$3-C13 -> 1142875.3 | F14: =C14-F13 -> 939697.48 | H14: =F14-H13 -> 736519.65 | J14: =H14-J13 -> 533341.82 | L14: =J14-L13 -> 330163.98 | N14: =L14-N13 -> 330163.98 | T14: =N14-T13 -> 266670.91 | Z14: =T14-Z13 -> 203177.83
A15: Cumul facturation | C15: =C13 -> 126986.15 | D15: =C15+D13 -> 126986.15 | E15: =D15+E13 -> 126986.15 | F15: =E15+F13 -> 330163.98 | G15: =F15+G13 -> 330163.98 | H15: =G15+H13 -> 533341.82 | I15: =H15+I13 -> 533341.82 | J15: =I15+J13 -> 736519.65 | K15: =J15+K13 -> 736519.65 | ... S15: =R15+S13 -> 939697.48 | T15: =T13+S15 -> 1003190.6 | U15: =U13+T15 -> 1003190.6 | V15: =V13+U15 -> 1003190.6 | W15: =W13+V15 -> 1003190.6 | X15: =X13+W15 -> 1003190.6 | Y15: =Y13+X15 -> 1003190.6 | Z15: =Z13+Y15 -> 1066683.6
A16: Cumul facturation % | C16: =C13/$D$3+B16 -> 0.1 | D16: =D13/$D$3+C16 -> 0.1 | E16: =E13/$D$3+D16 -> 0.1 | F16: =F13/$D$3+E16 -> 0.26 | G16: =G13/$D$3+F16 -> 0.26 | H16: =H13/$D$3+G16 -> 0.42 | I16: =I13/$D$3+H16 -> 0.42 | J16: =J13/$D$3+I16 -> 0.58 | ... Z16: =Z13/$D$3+Y16 -> 0.84
A17: Reste à facturer % | C17: =1-C16 -> 0.9 | D17: =1-D16 -> 0.9 | E17: =1-E16 -> 0.9 | F17: =1-F16 -> 0.74 | G17: =1-G16 -> 0.74 | H17: =1-H16 -> 0.58 | I17: =1-I16 -> 0.58 | J17: =1-J16 -> 0.42 | ... Z17: =1-Z16 -> 0.16
A18: Date initiale | C18: 45357 | F18: 45449 | H18: 45510 | J18: 45571 | L18: 45632 | N18: 45694 | T18: 45875 | Z18: 46059
A19: Date prévisionnelle | C19: 45357 | F19: 45449 | H19: 45565 | J19: 45590 | L19: 45644 | N19: 45704 | T19: 45875 | Z19: 46059
A20: Date réelle | C20: 45365 | F20: 45496 | H20: 30/9/2024 | J20: 45593
A21: Statut | C21: Facturé | F21: Facturé | H21: Facturé | J21: Facturé
A22: Réglé (si facturé) O/N | C22: Oui | F22: Non | H22: Non | J22: Non
A23: Montant payé (Si réglé) | C23: 22969421
A24: Cumul payé | C24: =C23+B24 -> 22969421 | D24: =D23+C24 -> 22969421 | E24: =E23+D24 -> 22969421 | F24: =F23+E24 -> 22969421 | G24: =G23+F24 -> 22969421 | H24: =H23+G24 -> 22969421 | I24: =I23+H24 -> 22969421 | J24: =J23+I24 -> 22969421 | ... Z24: =Z23+Y24 -> 22969421
A25: Commentaires | C25: Payé le 21/08/2024

Sheet Recap Facturation (2)
A2: Dashboard | H2: Total contrat HT (DT) | I2: ='Fiche identification'!B26 -> 1269861.5 | J2: =J4*#REF! -> #REF!
H3: Total Rémunération (HT) | I3: 1171440.5
A4: Mois en cours | B4: =Dashboard!C22 -> 45997 | H4: Total contrat HT (FCFA) | I4: ='Fiche identification'!B22 -> 248992444 | J4: 222803390
B6: N° échéance | C6: Description | D6: % | E6: Devise | F6: Montant | G6: Date initiale | H6: Montant en TND | I6: Reste à facturer en TND | J6: Cumul facturation | K6: Cumul facturation % | L6: Reste à facturer % | M6: Date prévisionnelle | N6: Date réelle | O6: Statut | P6: Réglé (si facturé) O/N | Q6: Montant payé (Si réglé) | R6: Cumul payé | S6: Commentaires | T6: Commentaires2
A7: 45358 | B7: 1 | C7: Facture Sprint 1 | D7: 0.1 | E7: FCFA | F7: 22280339 | G7: =DATE(2024,3,6)+10 -> 45367 | H7: =F7*#REF! -> #REF! | I7: =$J$2-H7 -> #REF! | J7: =H7 -> #REF! | K7: =J7/$I$3 -> #REF! | L7: =100%-K7 -> #REF! | M7: =DATE(2024,3,6)+10 -> 45367 | N7: 45365 | O7: Facturé | P7: Oui | Q7: 22969421 | R7: 22969421 | S7: Payé le 21/08/2024
A8: 45450 | B8: 2 | C8: Facture Sprint 2+3+4 | D8: 0.16 | E8: FCFA | F8: 35767792 | G8: =DATE(2024,6,6)+10 -> 45459 | H8: =F8*#REF! -> #REF! | I8: =I7-H8 -> #REF! | J8: =H7+H8 -> #REF! | K8: =J8/$I$3 -> #REF! | L8: =100%-K8 -> #REF! | M8: =DATE(2024,6,6)+10 -> 45459 | N8: 45496 | O8: Facturé | P8: Non | R8: 22969421
A9: 45511 | B9: 3 | C9: Facture Sprint 5+6 | D9: 0.16 | E9: FCFA | F9: 35791642 | G9: =DATE(2024,8,6)+10 -> 45520 | H9: =F9*#REF! -> #REF! | I9: =I8-H9 -> #REF! | J9: =H7+H8+H9 -> #REF! | K9: =J9/$I$3 -> #REF! | L9: =100%-K9 -> #REF! | M9: =DATE(2024,9,20)+10 -> 45565 | N9: 30/9/2024 | O9: Facturé | P9: Non | R9: 22969421
A10: 45572 | B10: 4 | C10: Facture Sprint 7+8 | D10: 0.16 | E10: FCFA | F10: 35791642 | G10: =DATE(2024,10,6)+10 -> 45581 | H10: =F10*#REF! -> #REF! | I10: =I9-H10 -> #REF! | J10: =H7+H8+H9+H10 -> #REF! | K10: =J10/$I$3 -> #REF! | L10: =100%-K10 -> #REF! | M10: =DATE(2024,10,25) -> 45590 | N10: 45593 | O10: Facturé | P10: Non | R10: 22969421
A11: 45633 | B11: 5 | C11: Facture Sprint 9+10 | D11: 0.16 | E11: FCFA | F11: 35791642 | G11: =DATE(2024,12,6)+10 -> 45642 | H11: =F11*#REF! -> #REF! | I11: =I10-H11 -> #REF! | J11: =SUM(H7:H11) -> #REF! | K11: =J11/$I$3 -> #REF! | L11: =100%-K11 -> #REF! | M11: 45657 | N11: 45657 | O11: Facturé | P11: Non | R11: 22969421
A12: 45695 | B12: 6 | C12: Facture Sprint 11+12 | D12: 0.16 | E12: FCFA | F12: =J4*D12 -> 35648542 | G12: =DATE(2025,2,6)+10 -> 45704 | H12: =Tableau5[[#This Row],[Montant]]*#REF! -> #REF! | I12: =I11-H12 -> #REF! | J12: =SUM(H7:H12) -> #REF! | K12: =J12/$I$3 -> #REF! | L12: =100%-K12 -> #REF! | M12: 45704 | R12: 22969421
A13: 45876 | B13: 7 | C13: MNT 18 premiers mois | D13: 0.05 | E13: FCFA | F13: =J4*Tableau5[[#This Row],[%]] -> 11140170 | G13: =DATE(2025,8,6)+10 -> 45885 | H13: =Tableau5[[#This Row],[Montant]]*#REF! -> #REF! | I13: =I12-H13 -> #REF! | J13: =SUM(H7:H13) -> #REF! | K13: =J13/$I$3 -> #REF! | L13: =100%-K13 -> #REF! | M13: =DATE(2025,8,6)+10 -> 45885 | R13: 22969421
A14: 46060 | B14: 8 | C14: MNT 6 derniers mois | D14: 0.05 | E14: FCFA | F14: =J4*Tableau5[[#This Row],[%]] -> 11140170 | G14: =DATE(2026,2,6)+10 -> 46069 | H14: =Tableau5[[#This Row],[Montant]]*#REF! -> #REF! | I14: =I13-H14 -> #REF! | J14: =SUM(H7:H14) -> #REF! | K14: =J14/$I$3 -> #REF! | L14: =100%-K14 -> #REF! | M14: =DATE(2026,2,6)+10 -> 46069 | R14: 22969421

Sheet Coût Prévisionnel
A2: Dashboard
A4: Mois en cours
A6: Plan de charge | B6: 45323 | C6: 45352 | D6: 45383 | E6: 45413 | F6: 45444 | G6: 45474 | H6: 45505 | I6: 45536 | J6: 45566 | K6: 45597 | L6: 45627 | M6: 45658 | N6: 45689 | O6: 45717 | P6: 45748 | Q6: 45778 | R6: 45809 | S6: 45839 | T6: 45870 | U6: 45901 | V6: 45931 | W6: 45962 | X6: 45992 | Y6: 46023 | Z6: 46054
A7: Ahmed Hamadi | F7: 20 | G7: 20 | H7: 19 | I7: 20 | J7: 20 | K7: 0 | L7: 0 | M7: 0
A8: Asma Belghith | D8: 10 | F8: 10 | G8: 20 | H8: 15 | I8: 20 | J8: 20 | K8: 0 | L8: 0 | M8: 0
A9: Aymen Abid | E9: 20 | F9: 20 | G9: 20 | H9: 18 | I9: 18 | J9: 18 | K9: 10 | L9: 5 | M9: 0
A10: Dorsaf Babay | G10: 10 | H10: 10 | I10: 10 | J10: 10 | K10: 20 | L10: 10
A11: Faten Zenaidi | B11: 20 | C11: 20 | D11: 20 | E11: 20 | F11: 20 | G11: 20 | H11: 10 | I11: 10 | J11: 10 | K11: 15 | L11: 10 | M11: 15
A12: Hassen Ben Hamida | B12: 20 | C12: 20 | D12: 20 | E12: 20 | F12: 20 | G12: 20 | H12: 20 | I12: 20 | J12: 20 | K12: 15 | L12: 15 | M12: 5 | N12: 5 | O12: 1 | P12: 1 | Q12: 1 | R12: 1 | S12: 1 | T12: 1 | U12: 1 | V12: 1 | W12: 1 | X12: 1 | Y12: 1 | Z12: 1
A13: Islem Bensaid | G13: 20 | H13: 20 | I13: 20 | J13: 20 | K13: 15 | L13: 15 | M13: 5 | O13: 1 | P13: 1 | Q13: 1 | R13: 1 | S13: 1 | T13: 1 | U13: 1 | V13: 1 | W13: 1 | X13: 1 | Y13: 1 | Z13: 1
A14: Moataz Zenaidi | B14: 20 | C14: 20 | D14: 20 | E14: 20 | F14: 20 | G14: 20 | H14: 15 | I14: 20 | J14: 20 | K14: 15 | L14: 10 | M14: 20 | N14: 5 | O14: 1 | P14: 1 | Q14: 1 | R14: 1 | S14: 1 | T14: 1 | U14: 1 | V14: 1 | W14: 1 | X14: 1 | Y14: 1 | Z14: 1
A15: Nidhal Marouani | B15: 20 | C15: 20 | D15: 20 | E15: 20 | F15: 20 | G15: 20 | H15: 18 | I15: 20 | J15: 20 | K15: 20 | L15: 15 | M15: 10 | N15: 5 | O15: 1 | P15: 1 | Q15: 1 | R15: 1 | S15: 1 | T15: 1 | U15: 1 | V15: 1 | W15: 1 | X15: 1 | Y15: 1 | Z15: 1
A16: Rami Loulou | G16: 5 | H16: 5 | I16: 10 | J16: 10 | K16: 10 | L16: 10 | M16: 0 | O16: 1 | P16: 1 | Q16: 1 | R16: 1 | S16: 1 | T16: 1 | U16: 1 | V16: 1 | W16: 1 | X16: 1 | Y16: 1 | Z16: 1
A17: Slim Amiri | G17: 10
A18: Wafa Boussetta | B18: 15 | C18: 15 | D18: 15 | E18: 15 | F18: 15 | G18: 15 | H18: 10 | I18: 10 | J18: 10 | K18: 15 | L18: 10 | M18: 10
A19: Ahmed Amine AMIRI | B19: 20 | C19: 20 | D19: 20 | E19: 20 | F19: 20 | G19: 20 | H19: 20 | I19: 10 | J19: 15 | K19: 10 | L19: 10 | M19: 5 | N19: 5 | O19: 1 | P19: 1 | Q19: 1 | R19: 1 | S19: 1 | T19: 1 | U19: 1 | V19: 1 | W19: 1 | X19: 1 | Y19: 1 | Z19: 1
A20: Frais de mission (Perdiem) | W20: 28
A21: Frais de mission (Billet) | W21: 4
A22: Autres Frais
A23: Total | B23: =SUM(B7:B19) -> 115 | C23: =SUM(C7:C19) -> 115 | D23: =SUM(D7:D19) -> 125 | E23: =SUM(E7:E19) -> 135 | F23: =SUM(F7:F19) -> 165 | G23: =SUM(G7:G19) -> 220 | H23: =SUM(H7:H19) -> 180 | I23: =SUM(I7:I19) -> 188 | ... L23: =SUM(L7:L19) -> 110 | M23: 101 | N23: =SUM(N7:N19) -> 20 | O23: =SUM(O7:O19) -> 6 | P23: =SUM(P7:P19) -> 6 | Q23: =SUM(Q7:Q19) -> 6 | R23: =SUM(R7:R19) -> 6 | S23: =SUM(S7:S19) -> 6 | T23: =SUM(T7:T19) -> 6 | U23: =SUM(U7:U19) -> 6 | ... Z23: =SUM(Z7:Z19) -> 6
A24: Estimation To Complet (ETC) | B24: =SUM(B23:$Z$23)-B23 -> 1769 | C24: =SUM(C23:$Z$23)-C23 -> 1654 | D24: =SUM(D23:$Z$23)-D23 -> 1529 | E24: =SUM(E23:$Z$23)-E23 -> 1394 | F24: =SUM(F23:$Z$23)-F23 -> 1229 | G24: =SUM(G23:$Z$23)-G23 -> 1009 | H24: =SUM(H23:$Z$23)-H23 -> 829 | I24: =SUM(I23:$Z$23)-I23 -> 641 | ... Z24: =SUM(Z23:$Z$23)-Z23 -> 0
A25: Coût Prévisionnel
A26: Ahmed Hamadi | B26: =B7*TCC!$C6 -> 0 | C26: =C7*TCC!$C6 -> 0 | D26: =D7*TCC!$C6 -> 0 | E26: =E7*TCC!$C6 -> 0 | F26: =F7*TCC!$C6 -> 2802.4242 | G26: =G7*TCC!$C6 -> 2802.4242 | H26: =H7*TCC!$C6 -> 2662.303 | I26: =I7*TCC!$C6 -> 2802.4242 | ... L26: =L7*TCC!$C6 -> 0 | M26: =M7*TCC!$E6 -> 0 | N26: =N7*TCC!$E6 -> 0 | O26: =O7*TCC!$E6 -> 0 | P26: =P7*TCC!$E6 -> 0 | Q26: =Q7*TCC!$E6 -> 0 | R26: =R7*TCC!$E6 -> 0 | S26: =S7*TCC!$E6 -> 0 | T26: =T7*TCC!$E6 -> 0 | ... Z26: =Z7*TCC!$E6 -> 0
A27: Asma Belghith | B27: =B8*TCC!$C7 -> 0 | C27: =C8*TCC!$C7 -> 0 | D27: =D8*TCC!$C7 -> 2558.4297 | E27: =E8*TCC!$C7 -> 0 | F27: =F8*TCC!$C7 -> 2558.4297 | G27: =G8*TCC!$C7 -> 5116.8594 | H27: =H8*TCC!$C7 -> 3837.6445 | I27: =I8*TCC!$C7 -> 5116.8594 | ... L27: =L8*TCC!$C7 -> 0 | M27: =M8*TCC!$E7 -> 0 | N27: =N8*TCC!$E7 -> 0 | O27: =O8*TCC!$E7 -> 0 | P27: =P8*TCC!$E7 -> 0 | Q27: =Q8*TCC!$E7 -> 0 | R27: =R8*TCC!$E7 -> 0 | S27: =S8*TCC!$E7 -> 0 | T27: =T8*TCC!$E7 -> 0 | ... Z27: =Z8*TCC!$E7 -> 0
A28: Aymen Abid | B28: =B9*TCC!$C8 -> 0 | C28: =C9*TCC!$C8 -> 0 | D28: =D9*TCC!$C8 -> 0 | E28: =E9*TCC!$C8 -> 4647.6385 | F28: =F9*TCC!$C8 -> 4647.6385 | G28: =G9*TCC!$C8 -> 4647.6385 | H28: =H9*TCC!$C8 -> 4182.8747 | I28: =I9*TCC!$C8 -> 4182.8747 | ... L28: =L9*TCC!$C8 -> 1161.9096 | M28: =M9*TCC!$E8 -> 0 | N28: =N9*TCC!$E8 -> 0 | O28: =O9*TCC!$E8 -> 0 | P28: =P9*TCC!$E8 -> 0 | Q28: =Q9*TCC!$E8 -> 0 | R28: =R9*TCC!$E8 -> 0 | S28: =S9*TCC!$E8 -> 0 | T28: =T9*TCC!$E8 -> 0 | ... Z28: =Z9*TCC!$E8 -> 0
A29: Dorsaf Babay | B29: =B10*TCC!$C9 -> 0 | C29: =C10*TCC!$C9 -> 0 | D29: =D10*TCC!$C9 -> 0 | E29: =E10*TCC!$C9 -> 0 | F29: =F10*TCC!$C9 -> 0 | G29: =G10*TCC!$C9 -> 6067.1234 | H29: =H10*TCC!$C9 -> 6067.1234 | I29: =I10*TCC!$C9 -> 6067.1234 | ... L29: =L10*TCC!$C9 -> 6067.1234 | M29: =M10*TCC!$E9 -> 0 | N29: =N10*TCC!$E9 -> 0 | O29: =O10*TCC!$E9 -> 0 | P29: =P10*TCC!$E9 -> 0 | Q29: =Q10*TCC!$E9 -> 0 | R29: =R10*TCC!$E9 -> 0 | S29: =S10*TCC!$E9 -> 0 | T29: =T10*TCC!$E9 -> 0 | ... Z29: =Z10*TCC!$E9 -> 0
A30: Faten Zenaidi | B30: =B11*TCC!$C10 -> 9698.0997 | C30: =C11*TCC!$C10 -> 9698.0997 | D30: =D11*TCC!$C10 -> 9698.0997 | E30: =E11*TCC!$C10 -> 9698.0997 | F30: =F11*TCC!$C10 -> 9698.0997 | G30: =G11*TCC!$C10 -> 9698.0997 | H30: =H11*TCC!$C10 -> 4849.0499 | I30: =I11*TCC!$C10 -> 4849.0499 | ... L30: =L11*TCC!$C10 -> 4849.0499 | M30: =M11*TCC!$E10 -> 9079.8274 | N30: =N11*TCC!$E10 -> 0 | O30: =O11*TCC!$E10 -> 0 | P30: =P11*TCC!$E10 -> 0 | Q30: =Q11*TCC!$E10 -> 0 | R30: =R11*TCC!$E10 -> 0 | S30: =S11*TCC!$E10 -> 0 | T30: =T11*TCC!$E10 -> 0 | ... Z30: =Z11*TCC!$E10 -> 0
A31: Hassen Ben Hamida | B31: =B12*TCC!$C11 -> 7900.8771 | C31: =C12*TCC!$C11 -> 7900.8771 | D31: =D12*TCC!$C11 -> 7900.8771 | E31: =E12*TCC!$C11 -> 7900.8771 | F31: =F12*TCC!$C11 -> 7900.8771 | G31: =G12*TCC!$C11 -> 7900.8771 | H31: =H12*TCC!$C11 -> 7900.8771 | I31: =I12*TCC!$C11 -> 7900.8771 | ... L31: =L12*TCC!$C11 -> 5925.6578 | M31: =M12*TCC!$E11 -> 2332.19 | N31: =N12*TCC!$E11 -> 2332.19 | O31: =O12*TCC!$E11 -> 466.43801 | P31: =P12*TCC!$E11 -> 466.43801 | Q31: =Q12*TCC!$E11 -> 466.43801 | R31: =R12*TCC!$E11 -> 466.43801 | S31: =S12*TCC!$E11 -> 466.43801 | T31: =T12*TCC!$E11 -> 466.43801 | ... Z31: =Z12*TCC!$E11 -> 466.43801
A32: Islem Bensaid | B32: =B13*TCC!$C12 -> 0 | C32: =C13*TCC!$C12 -> 0 | D32: =D13*TCC!$C12 -> 0 | E32: =E13*TCC!$C12 -> 0 | F32: =F13*TCC!$C12 -> 0 | G32: =G13*TCC!$C12 -> 3090.9091 | H32: =H13*TCC!$C12 -> 3090.9091 | I32: =I13*TCC!$C12 -> 3090.9091 | ... L32: =L13*TCC!$C12 -> 2318.1818 | M32: =M13*TCC!$E12 -> 1604.0125 | N32: =N13*TCC!$E12 -> 0 | O32: =O13*TCC!$E12 -> 320.8025 | P32: =P13*TCC!$E12 -> 320.8025 | Q32: =Q13*TCC!$E12 -> 320.8025 | R32: =R13*TCC!$E12 -> 320.8025 | S32: =S13*TCC!$E12 -> 320.8025 | T32: =T13*TCC!$E12 -> 320.8025 | ... Z32: =Z13*TCC!$E12 -> 320.8025
A33: Moataz Zenaidi | B33: =B14*TCC!$C13 -> 2928.6364 | C33: =C14*TCC!$C13 -> 2928.6364 | D33: =D14*TCC!$C13 -> 2928.6364 | E33: =E14*TCC!$C13 -> 2928.6364 | F33: =F14*TCC!$C13 -> 2928.6364 | G33: =G14*TCC!$C13 -> 2928.6364 | H33: =H14*TCC!$C13 -> 2196.4773 | I33: =I14*TCC!$C13 -> 2928.6364 | ... L33: =L14*TCC!$C13 -> 1464.3182 | M33: =M14*TCC!$E13 -> 5950.4458 | N33: =N14*TCC!$E13 -> 1487.6115 | O33: =O14*TCC!$E13 -> 297.52229 | P33: =P14*TCC!$E13 -> 297.52229 | Q33: =Q14*TCC!$E13 -> 297.52229 | R33: =R14*TCC!$E13 -> 297.52229 | S33: =S14*TCC!$E13 -> 297.52229 | T33: =T14*TCC!$E13 -> 297.52229 | ... Z33: =Z14*TCC!$E13 -> 297.52229
A34: Nidhal Marouani | B34: =B15*TCC!$C14 -> 4587.0034 | C34: =C15*TCC!$C14 -> 4587.0034 | D34: =D15*TCC!$C14 -> 4587.0034 | E34: =E15*TCC!$C14 -> 4587.0034 | F34: =F15*TCC!$C14 -> 4587.0034 | G34: =G15*TCC!$C14 -> 4587.0034 | H34: =H15*TCC!$C14 -> 4128.303 | I34: =I15*TCC!$C14 -> 4587.0034 | ... L34: =L15*TCC!$C14 -> 3440.2525 | M34: =M15*TCC!$E14 -> 3437.6272 | N34: =N15*TCC!$E14 -> 1718.8136 | O34: =O15*TCC!$E14 -> 343.76272 | P34: =P15*TCC!$E14 -> 343.76272 | Q34: =Q15*TCC!$E14 -> 343.76272 | R34: =R15*TCC!$E14 -> 343.76272 | S34: =S15*TCC!$E14 -> 343.76272 | T34: =T15*TCC!$E14 -> 343.76272 | ... Z34: =Z15*TCC!$E14 -> 343.76272
A35: Rami Loulou | B35: =B16*TCC!$C15 -> 0 | C35: =C16*TCC!$C15 -> 0 | D35: =D16*TCC!$C15 -> 0 | E35: =E16*TCC!$C15 -> 0 | F35: =F16*TCC!$C15 -> 0 | G35: =G16*TCC!$C15 -> 4845.3368 | H35: =H16*TCC!$C15 -> 4845.3368 | I35: =I16*TCC!$C15 -> 9690.6737 | ... L35: =L16*TCC!$C15 -> 9690.6737 | M35: =M16*TCC!$E15 -> 0 | N35: =N16*TCC!$E15 -> 0 | O35: =O16*TCC!$E15 -> 958.42999 | P35: =P16*TCC!$E15 -> 958.42999 | Q35: =Q16*TCC!$E15 -> 958.42999 | R35: =R16*TCC!$E15 -> 958.42999 | S35: =S16*TCC!$E15 -> 958.42999 | T35: =T16*TCC!$E15 -> 958.42999 | ... Z35: =Z16*TCC!$E15 -> 958.42999
A36: Slim Amiri | B36: =B17*TCC!$C16 -> 0 | C36: =C17*TCC!$C16 -> 0 | D36: =D17*TCC!$C16 -> 0 | E36: =E17*TCC!$C16 -> 0 | F36: =F17*TCC!$C16 -> 0 | G36: =G17*TCC!$C16 -> 1594.5459 | H36: =H17*TCC!$C16 -> 0 | I36: =I17*TCC!$C16 -> 0 | ... L36: =L17*TCC!$C16 -> 0 | M36: =M17*TCC!$E16 -> 0 | N36: =N17*TCC!$E16 -> 0 | O36: =O17*TCC!$E16 -> 0 | P36: =P17*TCC!$E16 -> 0 | Q36: =Q17*TCC!$E16 -> 0 | R36: =R17*TCC!$E16 -> 0 | S36: =S17*TCC!$E16 -> 0 | T36: =T17*TCC!$E16 -> 0 | ... Z36: =Z17*TCC!$E16 -> 0
A37: Wafa Boussetta | B37: =B18*TCC!$C17 -> 10739.583 | C37: =C18*TCC!$C17 -> 10739.583 | D37: =D18*TCC!$C17 -> 10739.583 | E37: =E18*TCC!$C17 -> 10739.583 | F37: =F18*TCC!$C17 -> 10739.583 | G37: =G18*TCC!$C17 -> 10739.583 | H37: =H18*TCC!$C17 -> 7159.7218 | I37: =I18*TCC!$C17 -> 7159.7218 | ... L37: =L18*TCC!$C17 -> 7159.7218 | M37: =M18*TCC!$E17 -> 8651.0884 | N37: =N18*TCC!$E17 -> 0 | O37: =O18*TCC!$E17 -> 0 | P37: =P18*TCC!$E17 -> 0 | Q37: =Q18*TCC!$E17 -> 0 | R37: =R18*TCC!$E17 -> 0 | S37: =S18*TCC!$E17 -> 0 | T37: =T18*TCC!$E17 -> 0 | ... Z37: =Z18*TCC!$E17 -> 0
A38: Ahmed Amine AMIRI | B38: =B19*TCC!$C18 -> 3574.2134 | C38: =C19*TCC!$C18 -> 3574.2134 | D38: =D19*TCC!$C18 -> 3574.2134 | E38: =E19*TCC!$C18 -> 3574.2134 | F38: =F19*TCC!$C18 -> 3574.2134 | G38: =G19*TCC!$C18 -> 3574.2134 | H38: =H19*TCC!$C18 -> 3574.2134 | I38: =I19*TCC!$C18 -> 1787.1067 | ... L38: =L19*TCC!$C18 -> 1787.1067 | M38: =M19*TCC!$E18 -> 982.90869 | N38: =N19*TCC!$E18 -> 982.90869 | O38: =O19*TCC!$E18 -> 196.58174 | P38: =P19*TCC!$E18 -> 196.58174 | Q38: =Q19*TCC!$E18 -> 196.58174 | R38: =R19*TCC!$E18 -> 196.58174 | S38: =S19*TCC!$E18 -> 196.58174 | T38: =T19*TCC!$E18 -> 196.58174 | ... Z38: =Z19*TCC!$E18 -> 196.58174
A39: Frais de mission (Perdiem) | H39: =H20*#REF! -> #REF! | I39: =I20*#REF! -> #REF! | J39: =J20*#REF! -> #REF! | K39: =K20*#REF! -> #REF! | L39: =L20*#REF! -> #REF! | M39: =M20*#REF! -> #REF! | N39: =N20*#REF! -> #REF! | O39: =O20*#REF! -> #REF! | ... Z39: =Z20*#REF! -> #REF!
A40: Frais de mission (Billet) | H40: =H21*#REF! -> #REF! | I40: =I21*#REF! -> #REF! | J40: =J21*#REF! -> #REF! | K40: =K21*#REF! -> #REF! | L40: =L21*#REF! -> #REF! | M40: =M21*#REF! -> #REF! | N40: =N21*#REF! -> #REF! | O40: =O21*#REF! -> #REF! | ... Z40: =Z21*#REF! -> #REF!
A41: Autres Frais
A42: Total | B42: =SUM(B26:B41) -> 39428.413 | C42: =SUM(C26:C41) -> 39428.413 | D42: =SUM(D26:D41) -> 41986.842 | E42: =SUM(E26:E41) -> 44076.051 | F42: =SUM(F26:F41) -> 49436.905 | G42: =SUM(G26:G41) -> 67593.25 | H42: =SUM(H26:H41) -> #REF! | I42: =SUM(I26:I41) -> #REF! | ... Z42: =SUM(Z26:Z41) -> #REF!
A43: Cumul | B43: =SUM(B$42:$Z42)-B42 -> #REF! | C43: =SUM(C$42:$Z42)-C42 -> #REF! | D43: =SUM(D$42:$Z42)-D42 -> #REF! | E43: =SUM(E$42:$Z42)-E42 -> #REF! | F43: =SUM(F$42:$Z42)-F42 -> #REF! | G43: =SUM(G$42:$Z42)-G42 -> #REF! | H43: =SUM(H$42:$Z42)-H42 -> #REF! | I43: =SUM(I$42:$Z42)-I42 -> #REF! | ... Z43: =SUM(Z$42:$Z42)-Z42 -> #REF!

Sheet Coût réel Actualisé
A2: Dashboard
A4: Mois en cours | B4: =Dashboard!C22 -> 45997
A6: Imputation Actuel | B6: 45328 | C6: 45357 | D6: 45388 | E6: 45418 | F6: 45449 | G6: 45479 | H6: 45510 | I6: 45541 | J6: 45571 | K6: 45602 | L6: 45632 | M6: 45663 | N6: 45689 | O6: 45717 | P6: 45748 | Q6: 45778 | R6: 45809 | S6: 45839 | T6: 45870 | U6: 45901 | V6: 45931 | W6: 45962 | X6: 45992 | Y6: 46023 | Z6: 46054
A7: Ahmed HAMADI | B7: 0 | C7: 0 | D7: 20 | E7: 20 | F7: 20 | G7: 18 | H7: 17 | I7: 18 | J7: 12 | K7: 0 | L7: 0 | M7: 0 | N7: 0
A8: ASMA BELGHUITH | B8: 0 | C8: 0 | D8: 0 | E8: 0 | F8: 9 | G8: 12.5 | H8: 13 | I8: 15.6875 | J8: 0 | K8: 0 | L8: 0 | M8: 0 | N8: 0
A9: AYMEN ABID | B9: 0 | C9: 6 | D9: 6 | E9: 16 | F9: 13 | G9: 16 | H9: 19 | I9: 13.5 | J9: 7.5 | K9: 15 | L9: 5.5 | M9: 0 | N9: 0 | O9: 0 | P9: 0.5 | Q9: 0 | R9: =25/8 -> 3.125 | S9: =2/8 -> 0.25 | T9: 0 | X9: =4/8 -> 0.5
A10: DORSAF BABAY | B10: 0 | C10: 0 | D10: 0 | E10: 0 | F10: 0 | G10: 11 | H10: 10 | I10: 10 | J10: 13.875 | K10: 10 | L10: 19 | M10: 9 | N10: 6 | O10: 0 | P10: 0 | Q10: 0 | R10: 0 | S10: 0 | T10: 0
A11: FATEN ZNAIDI | B11: 18 | C11: 19 | D11: 20 | E11: 18 | F11: 15 | G11: 14 | H11: 14.75 | I11: 18 | J11: 14.625 | K11: 19.125 | L11: 17.75 | M11: 16 | N11: 11.375 | O11: 4.5 | P11: 0.125 | Q11: 0 | R11: 0 | S11: 0 | T11: =2/8 -> 0.25
A12: HASSEN BEN HMIDA | B12: 18 | C12: 18 | D12: 22 | E12: 18 | F12: 19 | G12: 22 | H12: 17.75 | I12: 20.5 | J12: 19.25 | K12: 20 | L12: 19.75 | M12: 10 | N12: 5 | O12: =3/8 -> 0.375 | P12: =28/8 -> 3.5 | Q12: 0 | R12: =2/8 -> 0.25 | S12: 0.5 | T12: =26/8 -> 3.25 | U12: =18/8 -> 2.25 | V12: =24/8 -> 3 | W12: =8/8 -> 1
A13: ISLEM BEN SAID | B13: 0 | C13: 0 | D13: 0 | E13: 7 | F13: 2 | G13: 22 | H13: 13.5 | I13: 21 | J13: 18.875 | K13: 20.25 | L13: 18 | M13: 7.625 | N13: 1.5 | O13: =21/8 -> 2.625 | P13: =1/8 -> 0.125 | Q13: 1 | R13: 0 | S13: =11/8 -> 1.375 | T13: 0 | V13: =1/8 -> 0.125 | W13: =10/8 -> 1.25
A14: MOATEZ ZNAIDI | B14: 20 | C14: 17 | D14: 21 | E14: 20 | F14: 20 | G14: 22 | H14: 12.75 | I14: 20.625 | J14: 20.75 | K14: 20.5 | L14: 7.5 | M14: 11.5 | N14: 10.5 | O14: =34/8 -> 4.25 | P14: 0.5 | Q14: 0.5 | R14: 0 | S14: 0 | T14: 0
A15: NIDHAL MAROUANI | B15: 18 | C15: 19 | D15: 23 | E15: 20 | F15: 20 | G15: 22 | H15: 19 | I15: 17 | J15: 20 | K15: 19 | L15: 20 | M15: 11 | N15: 4 | O15: 0 | P15: 0 | Q15: 0 | R15: 0 | S15: 0 | T15: 0
A16: RAMI LOULOU | B16: 0 | C16: 0 | D16: 0 | E16: 2 | F16: 6 | G16: 12 | H16: 5.5 | I16: 13.5 | J16: 10.8125 | K16: 12.25 | L16: 14.5 | M16: 1.5 | N16: 0.625 | O16: 3 | P16: =26/8 -> 3.25 | Q16: =2/8 -> 0.25 | R16: =10/8 -> 1.25 | S16: 0.5 | W16: =1/8 -> 0.125
A17: WAFA BOUSETTA | B17: 11 | C17: 15 | D17: 15 | E17: 10 | F17: 15 | G17: 15 | H17: 15.5 | I17: 15.5 | J17: 12 | K17: 12 | L17: 17.5 | M17: 18.5 | N17: 5 | O17: 0 | P17: 0 | Q17: 0 | R17: 0
A18: AHMED AMINE AMIRI | B18: 19 | C18: 17 | D18: 16 | E18: 10 | F18: 17 | G18: 21 | H18: 17 | I18: 10.5 | J18: 17 | K18: 6 | L18: 5 | M18: 6 | N18: 5 | O18: 0 | P18: =12/8 -> 1.5 | Q18: 0 | R18: 0 | S18: 0 | T18: =32/8 -> 4 | U18: =24/8 -> 3 | V18: =44/8 -> 5.5 | X18: =68/8 -> 8.5
A19: WAFA CHAABENI | B19: 14 | C19: 14 | D19: 18 | E19: 15 | F19: 16 | G19: 0 | H19: 0 | I19: 7 | J19: 1 | K19: 11 | L19: 0 | M19: 2 | N19: 0
A20: FARAH BOUAKLINE | B20: 0 | C20: 0 | D20: 0 | E20: 8 | F20: 9 | G20: 0 | H20: 0 | I20: 0 | J20: 0 | K20: 0 | L20: 0 | M20: 0 | N20: 0 | O20: 0 | P20: 0 | Q20: 0 | R20: 0 | S20: 0 | T20: 0
A21: Syrine Dridi | B21: 0 | C21: 0 | D21: 25 | E21: 20 | F21: 20 | G21: 10 | H21: 0 | I21: 17.75 | J21: 20 | K21: 19 | L21: 20 | M21: 4.75 | N21: 0 | O21: 0 | P21: 0 | Q21: 0 | R21: 0 | S21: 0 | T21: =4/8 -> 0.5
A22: Slim AMIRI | B22: 0 | C22: 0 | D22: 0 | E22: 0 | F22: 0 | G22: 13 | H22: 0 | I22: 0 | J22: 0 | K22: 0 | L22: 0 | M22: 0 | N22: 0 | O22: 0 | P22: 0 | Q22: 0 | R22: 0 | S22: 0 | T22: 0
A23: Makram MAHFOUDH | B23: 0 | C23: 0 | D23: 0 | E23: 0 | F23: 0 | G23: 0 | H23: 0 | I23: 0 | J23: 0 | K23: 0 | L23: 0 | M23: 0 | N23: 0 | O23: 0 | P23: 0 | Q23: 0 | R23: 0 | S23: 0 | T23: 0
A24: Safouene BEN GALI | B24: 0 | C24: 0 | D24: 0 | E24: 0 | F24: 0 | G24: 0 | H24: 0 | I24: 0 | J24: 0 | K24: 3.6 | L24: 3.625 | M24: 3.75 | N24: 0 | X24: =5/8 -> 0.625
A25: Autres Frais | B25: 0 | C25: 0 | D25: 0 | E25: 0 | F25: 0 | G25: 0 | H25: 0 | I25: 0 | J25: 0 | K25: 0 | L25: 0 | M25: 0
A26: Total | B26: =SUM(B7:B24) -> 118 | C26: =SUM(C7:C24) -> 125 | D26: =SUM(D7:D24) -> 186 | E26: =SUM(E7:E24) -> 184 | F26: =SUM(F7:F24) -> 201 | G26: =SUM(G7:G24) -> 230.5 | H26: =SUM(H7:H24) -> 174.75 | I26: =SUM(I7:I24) -> 218.5625 | ... Z26: =SUM(Z7:Z24) -> 0
A27: Cumul | B27: =B26 -> 118 | C27: =C26+B27 -> 243 | D27: =D26+C27 -> 429 | E27: =E26+D27 -> 613 | F27: =F26+E27 -> 814 | G27: =G26+F27 -> 1044.5 | H27: =H26+G27 -> 1219.25 | I27: =I26+H27 -> 1437.8125 | J27: =J26+I27 -> 1625.5 | ... Z27: =Z26+Y27 -> 2199.1
A28: Coût Actuel
A29: Ahmed HAMADI | B29: 0 | C29: 0 | D29: 0 | E29: 0 | F29: =F7*TCC!$C$6 -> 2802.4242 | G29: =G7*TCC!$C$6 -> 2522.1818 | H29: =H7*TCC!$C$6 -> 2382.0606 | I29: =I7*TCC!$C$6 -> 2522.1818 | J29: =J7*TCC!$C$6 -> 1681.4545 | K29: =K7*TCC!$C$6 -> 0 | L29: =L7*TCC!$C$6 -> 0 | M29: =M7*TCC!$E$6 -> 0 | N29: =N7*TCC!$E$6 -> 0 | O29: =O7*TCC!$E$6 -> 0 | P29: =P7*TCC!$E6 -> 0 | Q29: =Q7*TCC!$E6 -> 0 | R29: =R7*TCC!$E6 -> 0 | S29: =S7*TCC!$E6 -> 0 | T29: =T7*TCC!$E6 -> 0 | U29: =U7*TCC!$E6 -> 0 | V29: =V7*TCC!$E6 -> 0 | W29: =W7*TCC!$E6 -> 0 | ... Z29: =Z7*TCC!$E6 -> 0
A30: ASMA BELGHUITH | B30: =B8*TCC!$C$7 -> 0 | C30: =C8*TCC!$C$7 -> 0 | D30: =D8*TCC!$C$7 -> 0 | E30: =E8*TCC!$C$7 -> 0 | F30: =F8*TCC!$C$7 -> 2302.5867 | G30: =G8*TCC!$C$7 -> 3198.0371 | H30: =H8*TCC!$C$7 -> 3325.9586 | I30: =I8*TCC!$C$7 -> 4013.5366 | ... L30: =L8*TCC!$C$7 -> 0 | M30: =M8*TCC!$E$6 -> 0 | N30: =N8*TCC!$E$6 -> 0 | O30: =O8*TCC!$E$6 -> 0 | P30: =P8*TCC!$E7 -> 0 | Q30: =Q8*TCC!$E7 -> 0 | R30: =R8*TCC!$E7 -> 0 | S30: =S8*TCC!$E7 -> 0 | T30: =T8*TCC!$E7 -> 0 | U30: =U8*TCC!$E7 -> 0 | V30: =V8*TCC!$E7 -> 0 | W30: =W8*TCC!$E7 -> 0 | ... Z30: =Z8*TCC!$E7 -> 0
A31: AYMEN ABID | B31: =B9*TCC!$C$8 -> 0 | C31: =C9*TCC!$C$8 -> 1394.2916 | D31: =D9*TCC!$C$8 -> 1394.2916 | E31: =E9*TCC!$C$8 -> 3718.1108 | F31: =F9*TCC!$C$8 -> 3020.965 | G31: =G9*TCC!$C$8 -> 3718.1108 | H31: =H9*TCC!$C$8 -> 4415.2566 | I31: =I9*TCC!$C$8 -> 3137.156 | J31: =J9*TCC!$C$8 -> 1742.8644 | K31: =K9*TCC!C8 -> 3485.7289 | L31: =L9*TCC!$C$8 -> 1278.1006 | M31: =M9*TCC!$E$6 -> 0 | N31: =N9*TCC!$E$6 -> 0 | O31: =O9*TCC!$E$6 -> 0 | P31: =P9*TCC!$E8 -> 144.4904 | Q31: =Q9*TCC!$E8 -> 0 | R31: =R9*TCC!$E8 -> 903.06501 | S31: =S9*TCC!$E8 -> 72.245201 | T31: =T9*TCC!$E8 -> 0 | U31: =U9*TCC!$E8 -> 0 | V31: =V9*TCC!$E8 -> 0 | W31: =W9*TCC!$E8 -> 0 | ... Z31: =Z9*TCC!$E8 -> 0
A32: DORSAF BABAY | B32: =B10*TCC!$C$9 -> 0 | C32: =C10*TCC!$C$9 -> 0 | D32: =D10*TCC!$C$9 -> 0 | E32: =E10*TCC!$C$9 -> 0 | F32: =F10*TCC!$C$9 -> 0 | G32: =G10*TCC!$C$9 -> 6673.8358 | H32: =H10*TCC!$C$9 -> 6067.1234 | I32: =I10*TCC!$C$9 -> 6067.1234 | J32: =J10*TCC!$C$9 -> 8418.1337 | K32: =K10*TCC!C9 -> 6067.1234 | L32: =L10*TCC!$C$9 -> 11527.534 | M32: =M10*TCC!$E$6 -> 1387.2 | N32: =N10*TCC!$E$6 -> 924.8 | O32: =O10*TCC!$E$6 -> 0 | P32: =P10*TCC!$E9 -> 0 | Q32: =Q10*TCC!$E9 -> 0 | R32: =R10*TCC!$E9 -> 0 | S32: =S10*TCC!$E9 -> 0 | T32: =T10*TCC!$E9 -> 0 | U32: =U10*TCC!$E9 -> 0 | V32: =V10*TCC!$E9 -> 0 | W32: =W10*TCC!$E9 -> 0 | ... Z32: =Z10*TCC!$E9 -> 0
A33: FATEN ZNAIDI | B33: =B11*TCC!$C$10 -> 8728.2898 | C33: =C11*TCC!$C$10 -> 9213.1947 | D33: =D11*TCC!$C$10 -> 9698.0997 | E33: =E11*TCC!$C$10 -> 8728.2898 | F33: =F11*TCC!$C$10 -> 7273.5748 | G33: =G11*TCC!$C$10 -> 6788.6698 | H33: =H11*TCC!$C$10 -> 7152.3485 | I33: =I11*TCC!$C$10 -> 8728.2898 | J33: =J11*TCC!$C$10 -> 7091.7354 | K33: =K11*TCC!C10 -> 9273.8079 | L33: =L11*TCC!$C$10 -> 8607.0635 | M33: =M11*TCC!$E$6 -> 2466.1333 | N33: =N11*TCC!$E$6 -> 1753.2667 | O33: =O11*TCC!$E$6 -> 693.6 | P33: =P11*TCC!$E10 -> 75.665228 | Q33: =Q11*TCC!$E10 -> 0 | R33: =R11*TCC!$E10 -> 0 | S33: =S11*TCC!$E10 -> 0 | T33: =T11*TCC!$E10 -> 151.33046 | U33: =U11*TCC!$E10 -> 0 | V33: =V11*TCC!$E10 -> 0 | W33: =W11*TCC!$E10 -> 0 | ... Z33: =Z11*TCC!$E10 -> 0
A34: HASSEN BEN HMIDA | B34: =B12*TCC!$C$11 -> 7110.7894 | C34: =C12*TCC!$C$11 -> 7110.7894 | D34: =D12*TCC!$C$11 -> 8690.9648 | E34: =E12*TCC!$C$11 -> 7110.7894 | F34: =F12*TCC!$C$11 -> 7505.8332 | G34: =G12*TCC!$C$11 -> 8690.9648 | H34: =H12*TCC!$C$11 -> 7012.0284 | I34: =I12*TCC!$C$11 -> 8098.399 | J34: =J12*TCC!$C$11 -> 7604.5942 | K34: =K12*TCC!C11 -> 7900.8771 | L34: =L12*TCC!$C$11 -> 7802.1161 | M34: =M12*TCC!$E$6 -> 1541.3333 | N34: =N12*TCC!$E$6 -> 770.66667 | O34: =O12*TCC!$E$6 -> 57.8 | P34: =P12*TCC!$E11 -> 1632.533 | Q34: =Q12*TCC!$E11 -> 0 | R34: =R12*TCC!$E11 -> 116.6095 | S34: =S12*TCC!$E11 -> 233.219 | T34: =T12*TCC!$E11 -> 1515.9235 | U34: =U12*TCC!$E11 -> 1049.4855 | V34: =V12*TCC!$E11 -> 1399.314 | W34: =W12*TCC!$E11 -> 466.43801 | ... Z34: =Z12*TCC!$E11 -> 0
A35: ISLEM BEN SAID | B35: =B13*TCC!$C$12 -> 0 | C35: =C13*TCC!$C$12 -> 0 | D35: =D13*TCC!$C$12 -> 0 | E35: =E13*TCC!$C$12 -> 1081.8182 | F35: =F13*TCC!$C$12 -> 309.09091 | G35: =G13*TCC!$C$12 -> 3400 | H35: =H13*TCC!$C$12 -> 2086.3636 | I35: =I13*TCC!$C$12 -> 3245.4545 | J35: =J13*TCC!$C$12 -> 2917.0455 | K35: =K13*TCC!C12 -> 3129.5455 | L35: =L13*TCC!$C$12 -> 2781.8182 | M35: =M13*TCC!$E$6 -> 1175.2667 | N35: =N13*TCC!$E$6 -> 231.2 | O35: =O13*TCC!$E$6 -> 404.6 | P35: =P13*TCC!$E12 -> 40.100313 | Q35: =Q13*TCC!$E12 -> 320.8025 | R35: =R13*TCC!$E12 -> 0 | S35: =S13*TCC!$E12 -> 441.10344 | T35: =T13*TCC!$E12 -> 0 | U35: =U13*TCC!$E12 -> 0 | V35: =V13*TCC!$E12 -> 40.100313 | W35: =W13*TCC!$E12 -> 401.00313 | ... Z35: =Z13*TCC!$E12 -> 0
A36: MOATEZ ZNAIDI | B36: =B14*TCC!$C$13 -> 2928.6364 | C36: =C14*TCC!$C$13 -> 2489.3409 | D36: =D14*TCC!$C$13 -> 3075.0682 | E36: =E14*TCC!$C$13 -> 2928.6364 | F36: =F14*TCC!$C$13 -> 2928.6364 | G36: =G14*TCC!$C$13 -> 3221.5 | H36: =H14*TCC!$C$13 -> 1867.0057 | I36: =I14*TCC!$C$13 -> 3020.1562 | J36: =J14*TCC!$C$13 -> 3038.4602 | K36: =K14*TCC!C13 -> 3001.8523 | L36: =L14*TCC!$C$13 -> 1098.2386 | M36: =M14*TCC!$E$6 -> 1772.5333 | N36: =N14*TCC!$E$6 -> 1618.4 | O36: =O14*TCC!$E$6 -> 655.06667 | P36: =P14*TCC!$E13 -> 148.76115 | Q36: =Q14*TCC!$E13 -> 148.76115 | R36: =R14*TCC!$E13 -> 0 | S36: =S14*TCC!$E13 -> 0 | T36: =T14*TCC!$E13 -> 0 | U36: =U14*TCC!$E13 -> 0 | V36: =V14*TCC!$E13 -> 0 | W36: =W14*TCC!$E13 -> 0 | ... Z36: =Z14*TCC!$E13 -> 0
A37: NIDHAL MAROUANI | B37: =B15*TCC!$C$14 -> 4128.303 | C37: =C15*TCC!$C$14 -> 4357.6532 | D37: =D15*TCC!$C$14 -> 5275.0539 | E37: =E15*TCC!$C$14 -> 4587.0034 | F37: =F15*TCC!$C$14 -> 4587.0034 | G37: =G15*TCC!$C$14 -> 5045.7037 | H37: =H15*TCC!$C$14 -> 4357.6532 | I37: =I15*TCC!$C$14 -> 3898.9529 | J37: =J15*TCC!$C$14 -> 4587.0034 | K37: =K15*TCC!C14 -> 4357.6532 | L37: =L15*TCC!$C$14 -> 4587.0034 | M37: =M15*TCC!$E$6 -> 1695.4667 | N37: =N15*TCC!$E$6 -> 616.53333 | O37: =O15*TCC!$E$6 -> 0 | P37: =P15*TCC!$E14 -> 0 | Q37: =Q15*TCC!$E14 -> 0 | R37: =R15*TCC!$E14 -> 0 | S37: =S15*TCC!$E14 -> 0 | T37: =T15*TCC!$E14 -> 0 | U37: =U15*TCC!$E14 -> 0 | V37: =V15*TCC!$E14 -> 0 | W37: =W15*TCC!$E14 -> 0 | ... Z37: =Z15*TCC!$E14 -> 0
A38: RAMI LOULOU | B38: =B16*TCC!$C$13 -> 0 | C38: =C16*TCC!$C$13 -> 0 | D38: =D16*TCC!$C$13 -> 0 | E38: =E16*TCC!$C$13 -> 292.86364 | F38: =F16*TCC!$C$13 -> 878.59091 | G38: =G16*TCC!$C$15 -> 11628.808 | H38: =H16*TCC!$C$15 -> 5329.8705 | I38: =I16*TCC!$C$15 -> 13082.409 | J38: =J16*TCC!$C$15 -> 10478.041 | K38: =K16*TCC!C15 -> 11871.075 | L38: =L16*TCC!$C$15 -> 14051.477 | M38: =M16*TCC!$E$6 -> 231.2 | N38: =N16*TCC!$E$6 -> 96.333333 | O38: =O16*TCC!$E$6 -> 462.4 | P38: =P16*TCC!$E15 -> 3114.8975 | Q38: =Q16*TCC!$E15 -> 239.6075 | R38: =R16*TCC!$E15 -> 1198.0375 | S38: =S16*TCC!$E15 -> 479.215 | T38: =T16*TCC!$E15 -> 0 | U38: =U16*TCC!$E15 -> 0 | V38: =V16*TCC!$E15 -> 0 | W38: =W16*TCC!$E15 -> 119.80375 | ... Z38: =Z16*TCC!$E15 -> 0
A39: WAFA BOUSETTA | B39: =B17*TCC!$C$13 -> 1610.75 | C39: =C17*TCC!$C$13 -> 2196.4773 | D39: =D17*TCC!$C$13 -> 2196.4773 | E39: =E17*TCC!$C$13 -> 1464.3182 | F39: =F17*TCC!$C$13 -> 2196.4773 | G39: =G17*TCC!$C$16 -> 2391.8189 | H39: =H17*TCC!$C$16 -> 2471.5462 | I39: =I17*TCC!$C$16 -> 2471.5462 | J39: =J17*TCC!$C$16 -> 1913.4551 | K39: =K17*TCC!C16 -> 1913.4551 | L39: =L17*TCC!$C$16 -> 2790.4553 | M39: =M17*TCC!$E$6 -> 2851.4667 | N39: =N17*TCC!$E$6 -> 770.66667 | O39: =O17*TCC!$E$6 -> 0 | P39: =P17*TCC!$E16 -> 0 | Q39: =Q17*TCC!$E16 -> 0 | R39: =R17*TCC!$E16 -> 0 | S39: =S17*TCC!$E16 -> 0 | T39: =T17*TCC!$E16 -> 0 | U39: =U17*TCC!$E16 -> 0 | V39: =V17*TCC!$E16 -> 0 | W39: =W17*TCC!$E16 -> 0 | ... Z39: =Z17*TCC!$E16 -> 0
A40: AHMED AMINE AMIRI | B40: =B18*TCC!$C$13 -> 2782.2045 | C40: =C18*TCC!$C$13 -> 2489.3409 | D40: =D18*TCC!$C$13 -> 2342.9091 | E40: =E18*TCC!$C$13 -> 1464.3182 | F40: =F18*TCC!$C$13 -> 2489.3409 | G40: =G18*TCC!$C$17 -> 15035.416 | H40: =H18*TCC!$C$17 -> 12171.527 | I40: =I18*TCC!$C$17 -> 7517.7079 | J40: =J18*TCC!$C$17 -> 12171.527 | K40: =K18*TCC!C17 -> 4295.8331 | L40: =L18*TCC!$C$17 -> 3579.8609 | M40: =M18*TCC!$E$6 -> 924.8 | N40: =N18*TCC!$E$6 -> 770.66667 | O40: =O18*TCC!$E$6 -> 0 | P40: =P18*TCC!$E17 -> 1297.6633 | Q40: =Q18*TCC!$E17 -> 0 | R40: =R18*TCC!$E17 -> 0 | S40: =S18*TCC!$E17 -> 0 | T40: =T18*TCC!$E17 -> 3460.4353 | U40: =U18*TCC!$E17 -> 2595.3265 | V40: =V18*TCC!$E17 -> 4758.0986 | W40: =W18*TCC!$E17 -> 0 | ... Z40: =Z18*TCC!$E17 -> 0
A41: WAFA CHAABENI | B41: =B19*TCC!$C$18 -> 2501.9494 | C41: =C19*TCC!$C$13 -> 2050.0455 | D41: =D19*TCC!$C$13 -> 2635.7727 | E41: =E19*TCC!$C$13 -> 2196.4773 | F41: =F19*TCC!$C$13 -> 2342.9091 | G41: =G19*TCC!$C$18 -> 0 | H41: =H19*TCC!$C$18 -> 0 | I41: =I19*TCC!$C$18 -> 1250.9747 | J41: =J19*TCC!$C$18 -> 178.71067 | K41: =K19*TCC!C18 -> 1965.8174 | L41: =L19*TCC!$C$18 -> 0 | M41: =M19*TCC!$E$6 -> 308.26667 | N41: =N19*TCC!$E$6 -> 0 | O41: =O19*TCC!$E$6 -> 0 | P41: =P19*TCC!$E18 -> 0 | Q41: =Q19*TCC!$E18 -> 0 | R41: =R19*TCC!$E18 -> 0 | S41: =S19*TCC!$E18 -> 0 | T41: =T19*TCC!$E18 -> 0 | U41: =U19*TCC!$E18 -> 0 | V41: =V19*TCC!$E18 -> 0 | W41: =W19*TCC!$E18 -> 0 | ... Z41: =Z19*TCC!$E18 -> 0
A42: FARAH BOUAKLINE | B42: =B20*TCC!$C$19 -> 0 | C42: =C20*TCC!$C$13 -> 0 | D42: =D20*TCC!$C$13 -> 0 | E42: =E20*TCC!$C$13 -> 1171.4545 | F42: =F20*TCC!$C$13 -> 1317.8864 | G42: =G20*TCC!$C$19 -> 0 | H42: =H20*TCC!$C$19 -> 0 | I42: =I20*TCC!$C$19 -> 0 | J42: =J20*TCC!$C$19 -> 0 | K42: =K20*TCC!C19 -> 0 | L42: =L20*TCC!$C$19 -> 0 | M42: =M20*TCC!$E$6 -> 0 | N42: =N20*TCC!$E$6 -> 0 | O42: =O20*TCC!$E$6 -> 0 | P42: =P20*TCC!$E19 -> 0 | Q42: =Q20*TCC!$E19 -> 0 | R42: =R20*TCC!$E19 -> 0 | S42: =S20*TCC!$E19 -> 0 | T42: =T20*TCC!$E19 -> 0 | U42: =U20*TCC!$E19 -> 0 | V42: =V20*TCC!$E19 -> 0 | W42: =W20*TCC!$E19 -> 0 | ... Z42: =Z20*TCC!$E19 -> 0
A43: Syrine Dridi | B43: =B21*TCC!$C$20 -> 0 | C43: =C21*TCC!$C$13 -> 0 | D43: =D21*TCC!$C$13 -> 3660.7955 | E43: =E21*TCC!$C$13 -> 2928.6364 | F43: =F21*TCC!$C$13 -> 2928.6364 | G43: =G21*TCC!$C$20 -> 1422.4158 | H43: =H21*TCC!$C$20 -> 0 | I43: =I21*TCC!$C$20 -> 2524.788 | J43: =J21*TCC!$C$20 -> 2844.8315 | K43: =K21*TCC!C20 -> 2702.5899 | L43: =L21*TCC!$C$20 -> 2844.8315 | M43: =M21*TCC!$E$6 -> 732.13333 | N43: =N21*TCC!$E$6 -> 0 | O43: =O21*TCC!$E$6 -> 0 | P43: =P21*TCC!$E20 -> 0 | Q43: =Q21*TCC!$E20 -> 0 | R43: =R21*TCC!$E20 -> 0 | S43: =S21*TCC!$E20 -> 0 | T43: =T21*TCC!$E20 -> 85.805375 | U43: =U21*TCC!$E20 -> 0 | V43: =V21*TCC!$E20 -> 0 | W43: =W21*TCC!$E20 -> 0 | ... Z43: =Z21*TCC!$E20 -> 0
...

Sheet Recap Facturation
A2: Dashboard | H2: Total contrat HT (DT) | I2: ='Fiche identification'!B26 -> 1269861.5 | K2: Total frais: | L2: =I2-I3 -> 98420.962
H3: Totah Rémunération (HT) | I3: 1171440.5 | K3: Consommé: | L3: =Missions!J20+Missions!J21+Missions!J22 -> #REF!
A4: Mois en cours | B4: =Dashboard!C22 -> 45997 | H4: Total contrat HT (FCFA) | I4: ='Fiche identification'!B22 -> 248992444 | K4: Reste à consommer: | L4: =L2-L3 -> #REF!
B6: N° échéance | C6: Description | D6: % | E6: Devise | F6: Montant | G6: Date initiale | H6: Montant en TND | I6: Reste à facturer en TND | J6: Cumul facturation | K6: Cumul facturation % | L6: Reste à facturer % | M6: Date prévisionnelle | N6: Date réelle | O6: Statut | P6: Réglé (si facturé) O/N | Q6: Montant payé (Si réglé) | R6: Cumul payé | S6: Commentaires
A7: 45358 | B7: 1 | C7: Facture Sprint 1 | D7: 0.1 | E7: FCFA | F7: 22280339 | G7: =DATE(2024,3,6)+10 -> 45367 | H7: =F7*#REF! -> #REF! | I7: =$I$2-H7 -> #REF! | J7: =H7 -> #REF! | K7: =J7/$I$2 -> #REF! | L7: =100%-K7 -> #REF! | M7: =DATE(2024,3,6)+10 -> 45367 | N7: 45364 | O7: Facturé | P7: Oui | Q7: =22280339/#REF! -> #REF! | R7: =Q7 -> #REF! | S7: Facture n°24-02
A8: 45450 | B8: 2 | C8: Facture Sprint 2+3+4 | D8: 0.16 | E8: FCFA | F8: 35767792 | G8: =DATE(2024,6,6)+10 -> 45459 | H8: =F8*#REF! -> #REF! | I8: =I7-H8 -> #REF! | J8: =H7+H8 -> #REF! | K8: =J8/$I$2 -> #REF! | L8: =100%-K8 -> #REF! | M8: =DATE(2024,6,6)+10 -> 45459 | N8: 45496 | O8: Facturé | P8: Oui | Q8: 54655 | R8: =R7+Q8 -> #REF! | S8: Facture n°24-07
A9: 45511 | B9: 3 | C9: Facture Sprint 5+6 | D9: 0.16 | E9: FCFA | F9: 35791642 | G9: =DATE(2024,8,6)+10 -> 45520 | H9: =F9*#REF! -> #REF! | I9: =I8-H9 -> #REF! | J9: =H7+H8+H9 -> #REF! | K9: =J9/$I$2 -> #REF! | L9: =100%-K9 -> #REF! | M9: =DATE(2024,9,20)+10 -> 45565 | N9: 30/9/2024 | O9: Facturé | P9: Oui | Q9: 54346 | R9: =R8+Q9 -> #REF! | S9: Facture n°24-08
A10: 45572 | B10: 4 | C10: Facture Sprint 7+8 | D10: 0.16 | E10: FCFA | F10: 35791642 | G10: =DATE(2024,10,6)+10 -> 45581 | H10: =F10*#REF! -> #REF! | I10: =I9-H10 -> #REF! | J10: =H7+H8+H9+H10 -> #REF! | K10: =J10/$I$2 -> #REF! | L10: =100%-K10 -> #REF! | M10: =DATE(2024,10,25) -> 45590 | N10: 45593 | O10: Facturé | P10: Oui | Q10: 54286 | R10: =R9+Q10 -> #REF! | S10: Facture n°24-09
A11: 45633 | B11: 5 | C11: Facture Sprint 9+10 | D11: 0.16 | E11: FCFA | F11: 35791642 | G11: =DATE(2024,12,6)+10 -> 45642 | H11: =F11*#REF! -> #REF! | I11: =I10-H11 -> #REF! | J11: =SUM(H7:H11) -> #REF! | K11: =J11/$I$2 -> #REF! | L11: =100%-K11 -> #REF! | M11: 45657 | N11: 45657 | O11: Facturé | P11: Non | R11: =R10+Q11 -> #REF! | S11: Facture n°24-10
A12: 45695 | B12: 6 | C12: Facture Sprint 11+12 | D12: 0.16 | E12: FCFA | F12: 42692650 | G12: =DATE(2025,2,6)+10 -> 45704 | H12: =F12*#REF! -> #REF! | I12: =I11-H12 -> #REF! | J12: =SUM(H7:H12) -> #REF! | K12: =J12/$I$2 -> #REF! | L12: =100%-K12 -> #REF! | M12: 45704 | N12: 45744 | O12: Facturé | P12: Non | R12: =R11+Q12 -> #REF! | S12: Facture n°2025-05
A13: 45876 | B13: 7 | C13: MNT 18 premiers mois | D13: 0.05 | E13: FCFA | F13: 11223645 | G13: =DATE(2025,8,6)+10 -> 45885 | H13: =F13*#REF! -> #REF! | I13: =I12-H13 -> #REF! | J13: =SUM(H7:H13) -> #REF! | K13: =J13/$I$2 -> #REF! | L13: =100%-K13 -> #REF! | M13: =DATE(2025,8,6)+10 -> 45885 | N13: 45898 | O13: Facturé | P13: Non | R13: =R12+Q13 -> #REF! | S13: Facture n°2025-17
A14: 46060 | B14: 8 | C14: MNT 6 derniers mois | D14: 0.05 | E14: FCFA | G14: =DATE(2026,2,6)+10 -> 46069 | H14: =F14*#REF! -> #REF! | I14: =I13-H14 -> #REF! | J14: =SUM(H7:H14) -> #REF! | K14: =J14/$I$2 -> #REF! | L14: =100%-K14 -> #REF! | M14: =DATE(2026,2,6)+10 -> 46069 | R14: =R13+Q14 -> #REF!
F16: =D14*I3 -> 58572.025

Sheet S. Contractuelle
A2: Mois en cours | C2: Dashboard
G3: Période de développement | N3: Période de garantie
A4: Statut contractuel et financier | B4: 45323 | C4: 45352 | D4: 45383 | E4: 45413 | F4: 45444 | G4: 45474 | H4: 45505 | I4: 45536 | J4: 45566 | K4: 45597 | L4: 45627 | M4: 45658 | N4: 45689 | O4: 45717 | P4: 45748 | Q4: 45778 | R4: 45809 | S4: 45839 | T4: 45870 | U4: 45901 | V4: 45931 | W4: 45962 | X4: 45992 | Y4: 46023
A5: Devise Projet | B5: FCFA | C5: =$B$5 -> FCFA | D5: =$B$5 -> FCFA | E5: =$B$5 -> FCFA | F5: =$B$5 -> FCFA | G5: =$B$5 -> FCFA | H5: =$B$5 -> FCFA | I5: =$B$5 -> FCFA | J5: =$B$5 -> FCFA | ... Y5: =$B$5 -> FCFA
A6: Budget initial TO (incluant licences & soutraitances) | B6: 248992444 | C6: =$B$6 -> 248992444 | D6: =$B$6 -> 248992444 | E6: =$B$6 -> 248992444 | F6: =$B$6 -> 248992444 | G6: =$B$6 -> 248992444 | H6: =$B$6 -> 248992444 | I6: =$B$6 -> 248992444 | J6: =$B$6 -> 248992444 | ... Y6: =$B$6 -> 248992444
A7: Budget Licences & soutraitance (Initial) | B7: 0 | C7: =$B$7 -> 0 | D7: =$B$7 -> 0 | E7: =$B$7 -> 0 | F7: =$B$7 -> 0 | G7: =$B$7 -> 0 | H7: =$B$7 -> 0 | I7: =$B$7 -> 0 | J7: =$B$7 -> 0 | ... Y7: =$B$7 -> 0
A8: Avenant (O/N) | B8: Non | C8: =$B$8 -> Non | D8: =$B$8 -> Non | E8: =$B$8 -> Non | F8: =$B$8 -> Non | G8: =$B$8 -> Non | H8: =$B$8 -> Non | I8: =$B$8 -> Non | J8: =$B$8 -> Non | ... Y8: =$B$8 -> Non
A9: Montant Avenant | B9: 0 | C9: =$B$9 -> 0 | D9: =$B$9 -> 0 | E9: =$B$9 -> 0 | F9: =$B$9 -> 0 | G9: =$B$9 -> 0 | H9: =$B$9 -> 0 | I9: =$B$9 -> 0 | J9: =$B$9 -> 0 | ... Y9: =$B$9 -> 0
A10: Total avenants | B10: 0 | C10: =$B$10 -> 0 | D10: =$B$10 -> 0 | E10: =$B$10 -> 0 | F10: =$B$10 -> 0 | G10: =$B$10 -> 0 | H10: =$B$10 -> 0 | I10: =$B$10 -> 0 | J10: =$B$10 -> 0 | ... Y10: =$B$10 -> 0
A11: Budget total (avenants inclus) | B11: ='Fiche identification'!B22 -> 248992444 | C11: =$B$11 -> 248992444 | D11: =$B$11 -> 248992444 | E11: =$B$11 -> 248992444 | F11: =$B$11 -> 248992444 | G11: =$B$11 -> 248992444 | H11: =$B$11 -> 248992444 | I11: =$B$11 -> 248992444 | J11: =$B$11 -> 248992444 | ... Y11: =$B$11 -> 248992444
A12: Budget initial TO (incluant licences & soutraitances) en TND | B12: ='Fiche identification'!B23 -> 1269861.5 | C12: =$B$12 -> 1269861.5 | D12: =$B$12 -> 1269861.5 | E12: =$B$12 -> 1269861.5 | F12: =$B$12 -> 1269861.5 | G12: =$B$12 -> 1269861.5 | H12: =$B$12 -> 1269861.5 | I12: =$B$12 -> 1269861.5 | J12: =$B$12 -> 1269861.5 | ... P12: =$B$12 -> 1269861.5
A13: Budget Licences & soutraitance (Initial) en TND | B13: ='Fiche identification'!B18 -> 0 | C13: =$B$13 -> 0 | D13: =$B$13 -> 0 | E13: =$B$13 -> 0 | F13: =$B$13 -> 0 | G13: =$B$13 -> 0 | H13: =$B$13 -> 0 | I13: =$B$13 -> 0 | J13: =$B$13 -> 0 | ... P13: =$B$13 -> 0 | Q13: 0 | R13: 0 | S13: 0 | T13: 0 | U13: 0 | V13: 0 | W13: 0 | X13: 0 | Y13: 0
A14: Total avenants en TND | B14: 0 | C14: =$B$14 -> 0 | D14: =$B$14 -> 0 | E14: =$B$14 -> 0 | F14: =$B$14 -> 0 | G14: =$B$14 -> 0 | H14: =$B$14 -> 0 | I14: =$B$14 -> 0 | J14: =$B$14 -> 0 | ... Q14: =$B$14 -> 0 | R14: 0 | S14: 0 | T14: 0 | U14: 0 | V14: 0 | W14: 0 | X14: 0 | Y14: 0
A15: Budget total (avenants inclus) en TND | B15: 1269861.5 | C15: =B15+C14 -> 1269861.5 | D15: =C15+D14 -> 1269861.5 | E15: =D15+E14 -> 1269861.5 | F15: =E15+F14 -> 1269861.5 | G15: =F15+G14 -> 1269861.5 | H15: =G15+H14 -> 1269861.5 | I15: =H15+I14 -> 1269861.5 | J15: =I15+J14 -> 1269861.5 | ... M15: =L15+M14 -> 1269861.5 | N15: =$B$15 -> 1269861.5 | O15: =$B$15 -> 1269861.5 | P15: =$B$15 -> 1269861.5 | Q15: =$B$15 -> 1269861.5 | R15: =$B$15 -> 1269861.5 | S15: =$B$15 -> 1269861.5 | T15: =$B$15 -> 1269861.5
A16: PPR (Provision Pour Risques) en TND | B16: =B15*5% -> 63493.073 | C16: =C15*5% -> 63493.073 | D16: =D15*5% -> 63493.073 | E16: =E15*5% -> 63493.073 | F16: =F15*5% -> 63493.073 | G16: =G15*5% -> 63493.073 | H16: =H15*5% -> 63493.073 | I16: =I15*5% -> 63493.073 | ... Y16: =Y15*5% -> 0
A17: PPP(Provision Pour Pénalités) en TND | B17: 0 | C17: =$B$17 -> 0 | D17: =$B$17 -> 0 | E17: =$B$17 -> 0 | F17: =$B$17 -> 0 | G17: =$B$17 -> 0 | H17: =$B$17 -> 0 | I17: =$B$17 -> 0 | J17: =$B$17 -> 0 | ... Y17: =$B$17 -> 0
A18: Coût Total en TND (DI) | B18: 714333 | C18: =$B$18 -> 714333 | D18: =$B$18 -> 714333 | E18: =$B$18 -> 714333 | F18: =$B$18 -> 714333 | G18: =$B$18 -> 714333 | H18: =$B$18 -> 714333 | I18: =$B$18 -> 714333 | J18: =$B$18 -> 714333 | ... Y18: =$B$18 -> 714333
A19: Marge nette vendue % | B19: =B20/B15 -> 0.43747171 | C19: =C20/C15 -> 0.43747171 | D19: =D20/D15 -> 0.43747171 | E19: =E20/E15 -> 0.43747171 | F19: =F20/F15 -> 0.43747171 | G19: =G20/G15 -> 0.43747171 | H19: =H20/H15 -> 0.43747171 | I19: =I20/I15 -> 0.43747171 | ... Y19: =Y20/Y15 -> #DIV/0!
A20: Marge nette vendue en TND | B20: =B15-B18 -> 555528.46 | C20: =C15-C18 -> 555528.46 | D20: =D15-D18 -> 555528.46 | E20: =E15-E18 -> 555528.46 | F20: =F15-F18 -> 555528.46 | G20: =G15-G18 -> 555528.46 | H20: =H15-H18 -> 555528.46 | I20: =I15-I18 -> 555528.46 | ... Y20: =Y15-Y18 -> -714333
A21: Workload vendu avenants inclus en JH | B21: 1717 | C21: =$B$21 -> 1717 | D21: =$B$21 -> 1717 | E21: =$B$21 -> 1717 | F21: =$B$21 -> 1717 | G21: =$B$21 -> 1717 | H21: =$B$21 -> 1717 | I21: =$B$21 -> 1717 | J21: =$B$21 -> 1717 | ... Y21: =$B$21 -> 1717
A22: Workload initial en JH | B22: 1717 | C22: =$B$22 -> 1717 | D22: =$B$22 -> 1717 | E22: =$B$22 -> 1717 | F22: =$B$22 -> 1717 | G22: =$B$22 -> 1717 | H22: =$B$22 -> 1717 | I22: =$B$22 -> 1717 | J22: =$B$22 -> 1717 | ... Y22: =$B$22 -> 1717
A23: Workload avenants en JH | B23: 0 | C23: =$B$23 -> 0 | D23: =$B$23 -> 0 | E23: =$B$23 -> 0 | F23: =$B$23 -> 0 | G23: =$B$23 -> 0 | H23: =$B$23 -> 0 | I23: =$B$23 -> 0 | J23: =$B$23 -> 0 | ... Y23: =$B$23 -> 0
A24: Workload Garantie en JH | B24: 75 | C24: =$B$24 -> 75 | D24: =$B$24 -> 75 | E24: =$B$24 -> 75 | F24: =$B$24 -> 75 | G24: =$B$24 -> 75 | H24: =$B$24 -> 75 | I24: =$B$24 -> 75 | J24: =$B$24 -> 75 | ... Y24: =$B$24 -> 75
A25: Workload total en JH | B25: =SUM(B22:B24) -> 1792 | C25: =SUM(C22:C24) -> 1792 | D25: =SUM(D22:D24) -> 1792 | E25: =SUM(E22:E24) -> 1792 | F25: =SUM(F22:F24) -> 1792 | G25: =SUM(G22:G24) -> 1792 | H25: =SUM(H22:H24) -> 1792 | I25: =SUM(I22:I24) -> 1792 | ... Y25: =SUM(Y22:Y24) -> 1792
A26: Date Début | B26: 45323 | C26: 45323 | D26: 45323 | E26: 45323 | F26: 45323 | G26: 45323 | H26: 45323 | I26: 45323 | J26: 45323 | K26: 45323 | L26: 45323 | M26: 45323 | N26: 45323 | O26: 45689 | P26: 45689 | Q26: 45689 | R26: 45689 | S26: 45689 | T26: 45689 | U26: 45689 | V26: 45689 | W26: 45689 | X26: 45689 | Y26: 45689
A27: Date fin actualisée | B27: 46054 | C27: 46054 | D27: 46054 | E27: 46054 | F27: 46054 | G27: 46054 | H27: 46054 | I27: 46054 | J27: 46054 | K27: 46054 | L27: 46054 | M27: 46054 | N27: 46054 | O27: 46054 | P27: 46054 | Q27: 46054 | R27: 46054 | S27: 46054 | T27: 46054 | U27: 46054 | V27: 46054 | W27: 46054 | X27: 46054 | Y27: 46054
A28: Durée actualisée (j) | B28: 365 | C28: =$B$28 -> 365 | D28: =$B$28 -> 365 | E28: =$B$28 -> 365 | F28: =$B$28 -> 365 | G28: =$B$28 -> 365 | H28: =$B$28 -> 365 | I28: =$B$28 -> 365 | J28: =$B$28 -> 365 | ... Y28: =$B$28 -> 365
A29: Avancement délais | B29: =(B4-B26+30)/B28 -> 0.082191781 | C29: =(C4-C26+30)/C28 -> 0.16164384 | D29: =(D4-D26+30)/D28 -> 0.24657534 | E29: =(E4-E26+30)/E28 -> 0.32876712 | F29: =(F4-F26+30)/F28 -> 0.41369863 | G29: =(G4-G26+30)/G28 -> 0.49589041 | H29: =(H4-H26+30)/H28 -> 0.58082192 | I29: =(I4-I26+30)/I28 -> 0.66575342 | ... M29: =(M4-M26+30)/M28 -> 1

Sheet Situation actuelle
A2: Dashboard | C2: Total contrat HT (DT) | D2: ='Fiche identification'!B26 -> 1269861.5
C3: Total contrat HT (FCFA) | D3: ='Fiche identification'!B22 -> 248992444
A4: Mois en cours
B6: 45323 | C6: 45352 | D6: 45383 | E6: 45413 | F6: 45444 | G6: 45474 | H6: 45505 | I6: 45536 | J6: 45566 | K6: 45597 | L6: 45627 | M6: 45658 | N6: 45689 | O6: 45717 | P6: 45748 | Q6: 45778 | R6: 45809 | S6: 45839 | T6: 45870 | U6: 45901 | V6: 45931 | W6: 45962 | X6: 45992 | Y6: 46023 | Z6: 46054
A7: Phase actuelle | B7: Sprint 1 | C7: Sprint 2 | D7: Sprint 3 | E7: Sprint 4 | F7: Sprint 5 | G7: Sprint 6 | H7: Sprint 7 | I7: Sprint 8 | J7: Sprint 9 | K7: Sprint 10 | L7: Sprint 11 | M7: Sprint 12
A8: Earned Value % | B8: =2/12 -> 0.16666667 | C8: =3/12 -> 0.25 | D8: =4/12 -> 0.33333333 | E8: =4.5/12 -> 0.375 | F8: =5/12 -> 0.41666667 | G8: =6.5/12 -> 0.54166667 | H8: =7/12 -> 0.58333333 | I8: =8.5/12 -> 0.70833333 | J8: =9.2/12 -> 0.76666667 | K8: =10/12 -> 0.83333333
A9: Delivery % | B9: =1/12 -> 0.083333333 | C9: =2/12 -> 0.16666667 | D9: =3/12 -> 0.25 | E9: =4/12 -> 0.33333333 | F9: =5/12 -> 0.41666667 | G9: =6/12 -> 0.5 | H9: =7/12 -> 0.58333333 | I9: =8/12 -> 0.66666667 | J9: =9/12 -> 0.75 | K9: =9.5/12 -> 0.79166667
A10: Observations et faits marquants | B10: RAS | C10: RAS | D10: RAS | E10: RAS | F10: RAS | G10: RAS | H10: RAS | I10: RAS | J10: RAS | K10: RAS | L10: RAS | M10: RAS | N10: RAS | O10: RAS | P10: RAS | Q10: RAS | R10: RAS | S10: RAS | T10: RAS | U10: RAS | V10: RAS | W10: RAS | X10: RAS | Y10: RAS | Z10: RAS
A11: Charge totale consommée JH | B11: 118 | C11: 235 | D11: 430 | E11: 621 | F11: 828 | G11: 1059 | H11: ='Coût réel Actualisé'!H27 -> 1219.25 | I11: ='Coût réel Actualisé'!I27 -> 1437.8125 | J11: ='Coût réel Actualisé'!J27 -> 1625.5 | K11: ='Coût réel Actualisé'!K27 -> 1813.225
A12: RAF JH | B12: =1717-B11 -> 1599 | C12: =1717-C11 -> 1482 | D12: =1717-D11 -> 1287 | E12: =1717-E11 -> 1096 | F12: =1717-F11 -> 889 | G12: =1717-G11 -> 658 | H12: ='Coût Prévisionnel'!H24 -> 829 | I12: ='Coût Prévisionnel'!I24 -> 641 | J12: ='Coût Prévisionnel'!J24 -> 448 | K12: ='Coût Prévisionnel'!K24 -> 303 | L12: ='Coût Prévisionnel'!L24 -> 193 | M12: ='Coût Prévisionnel'!M24 -> 92 | N12: ='Coût Prévisionnel'!N24 -> 72 | O12: ='Coût Prévisionnel'!O24 -> 66 | ... Z12: ='Coût Prévisionnel'!Z24 -> 0
A13: Dérive JH | B13: =1717-B12-B11 -> 0 | C13: =1717-C12-C11 -> 0 | D13: =1717-D12-D11 -> 0 | E13: =1717-E12-E11 -> 0 | F13: =1717-F12-F11 -> 0 | G13: =1717-G12-G11 -> 0 | H13: =1717-H12-H11 -> -331.25 | I13: =1717-I12-I11 -> -361.8125 | ... Z13: =1717-Z12-Z11 -> 1717
A14: Cumul CA production TND | B14: =$D$2*B8 -> 211643.58 | C14: =$D$2*C8 -> 317465.37 | D14: =$D$2*D8 -> 423287.15 | E14: =$D$2*E8 -> 476198.05 | F14: =$D$2*F8 -> 529108.94 | G14: =$D$2*G8 -> 687841.63 | H14: =$D$2*H8 -> 740752.52 | I14: =$D$2*I8 -> 899485.2 | ... Z14: =$D$2*Z8 -> 0
A15: Total facturé TND | B15: =Avancement_Facturation!B15 -> 0 | C15: =Avancement_Facturation!C15 -> 126986.15 | D15: =Avancement_Facturation!D15 -> 126986.15 | E15: =Avancement_Facturation!E15 -> 126986.15 | F15: =Avancement_Facturation!F15 -> 330163.98 | G15: =Avancement_Facturation!G15 -> 330163.98 | H15: =Avancement_Facturation!H15 -> 533341.82 | I15: =Avancement_Facturation!I15 -> 533341.82 | ... U15: =Avancement_Facturation!U15 -> 1003190.6 | V15: =Avancement_Facturation!AH15 -> 0 | W15: =Avancement_Facturation!AI15 -> 0 | X15: =Avancement_Facturation!AJ15 -> 0 | Y15: =Avancement_Facturation!AK15 -> 0 | Z15: =Avancement_Facturation!AL15 -> 0
A16: FAE/Stock TND | B16: =B14-B15 -> 211643.58 | C16: =C14-C15 -> 190479.22 | D16: =D14-D15 -> 296301.01 | E16: =E14-E15 -> 349211.9 | F16: =F14-F15 -> 198944.96 | G16: =G14-G15 -> 357677.65 | H16: =H14-H15 -> 207410.71 | I16: =I14-I15 -> 366143.39 | ... Z16: =Z14-Z15 -> 0
A17: Coût actuel TND (cumul) | B17: ='Coût réel Actualisé'!B51 -> 35043.516 | C17: ='Coût réel Actualisé'!C51 -> 70702.303 | D17: ='Coût réel Actualisé'!D51 -> 114946.79 | E17: ='Coût réel Actualisé'!E51 -> 157206.51 | F17: ='Coût réel Actualisé'!F51 -> 204677.47 | G17: ='Coût réel Actualisé'!G51 -> 280353.7 | H17: ='Coût réel Actualisé'!H51 -> 338992.45 | I17: ='Coût réel Actualisé'!I51 -> 408571.12 | ... N17: ='Coût réel Actualisé'!N51 -> 630886.04 | O17: ='Coût réel Actualisé'!#REF! -> #REF! | P17: ='Coût réel Actualisé'!#REF! -> #REF! | Q17: ='Coût réel Actualisé'!#REF! -> #REF! | R17: ='Coût réel Actualisé'!O51 -> 633159.51 | S17: ='Coût réel Actualisé'!P51 -> 639613.62 | T17: ='Coût réel Actualisé'!Q51 -> 640322.79 | U17: ='Coût réel Actualisé'!R51 -> 642540.5 | V17: ='Coût réel Actualisé'!S51 -> 643766.28 | W17: ='Coût réel Actualisé'!T51 -> 648979.78 | X17: ='Coût réel Actualisé'!U51 -> 652624.59 | Y17: ='Coût réel Actualisé'!V51 -> 658822.1 | Z17: ='Coût réel Actualisé'!W51 -> 659809.35
A18: Marge % | B18: =B19/B14 -> 0.83442202 | C18: =C19/C14 -> 0.77729129 | D18: =D19/D14 -> 0.72844253 | E18: =E19/E14 -> 0.66987158 | F18: =F19/F14 -> 0.61316574 | G18: =G19/G14 -> 0.59241533 | H18: =H19/H14 -> 0.54236748 | I18: =I19/I14 -> 0.54577227 | ... Z18: =Z19/Z14 -> #DIV/0!
A19: Marge Net TND | B19: =B14-B17 -> 176600.06 | C19: =C14-C17 -> 246763.06 | D19: =D14-D17 -> 308340.37 | E19: =E14-E17 -> 318991.54 | F19: =F14-F17 -> 324431.48 | G19: =G14-G17 -> 407487.92 | H19: =H14-H17 -> 401760.08 | I19: =I14-I17 -> 490914.08 | ... Z19: =Z14-Z17 -> -659809.35
A22: Situation prévisionnelle à l'atterrissage (EAC) | B22: 45323 | C22: 45352 | D22: 45383 | E22: 45413 | F22: 45444 | G22: 45474 | H22: 45505 | I22: 45536 | J22: 45566 | K22: 45597 | L22: 45627 | M22: 45658 | N22: 45689 | O22: 45717 | P22: 45748 | Q22: 45778 | R22: 45809 | S22: 45839 | T22: 45870 | U22: 45901 | V22: 45931 | W22: 45962 | X22: 45992 | Y22: 46023 | Z22: 46054
A23: Coûts prévisionnels pour finaliser le projet TND | B23: =710000-B17 -> 674956.48 | C23: =710000-C17 -> 639297.7 | D23: =710000-D17 -> 595053.21 | E23: =710000-E17 -> 552793.49 | F23: =710000-F17 -> 505322.53 | G23: ='Coût Prévisionnel'!G43 -> #REF! | H23: ='Coût Prévisionnel'!H43 -> #REF! | I23: ='Coût Prévisionnel'!I43 -> #REF! | J23: ='Coût Prévisionnel'!J43 -> #REF! | K23: ='Coût Prévisionnel'!K43 -> #REF! | L23: ='Coût Prévisionnel'!L43 -> #REF! | M23: ='Coût Prévisionnel'!M43 -> #REF! | N23: ='Coût Prévisionnel'!N43 -> #REF! | ... W23: ='Coût Prévisionnel'!W43 -> #REF! | X23: ='Coût Prévisionnel'!X42 -> #REF! | Y23: ='Coût Prévisionnel'!Y42 -> #REF! | Z23: ='Coût Prévisionnel'!Z42 -> #REF!
